Workbook
Name DashFacilityNames: _xlfn.ANCHORARRAY(Dashboard!$B$74)
Name DashFacilityScope1: _xlfn.ANCHORARRAY(Dashboard!$C$74)
Name DashFacilityScope2: _xlfn.ANCHORARRAY(Dashboard!$D$74)
Name DashScope1SrcLabels: _xlfn.ANCHORARRAY(Dashboard!$E$65)
Name DashScope1SrcValues: _xlfn.ANCHORARRAY(Dashboard!$C$65)

Sheet Dashboard
B2: Reiniel Celgie Chan Analytics | AD2: ="Reporting year: "&$M$97 -> Reporting year: 2026
B3: Canadian Company X GHG Inventory Dashboard | AD3: Framework: GHG Protocol Corporate Standard
B4: Scope 1 and Scope 2 Emissions | AD4: Emission Factors: ECCC applicable to Calendar Year 2026
C33: MANAGEMENT INSIGHTS
C35: MANAGEMENT INSIGHT | L35: LIVE RESULT | U35: MANAGEMENT SIGNAL
C37: Inventory profile | L37: ="Scope 1 = "&TEXT($M$85,"0.0%")&" of total" -> Scope 1 = 67.5% of total | U37: =IF($M$85>=0.5,"Direct emissions dominate","Purchased electricity dominates") -> Direct emissions dominate
C40: Facility priority | L40: =$M$87&" = "&TEXT(IFERROR($M$88/$M$84,0),"0%")&" of total" -> Calgary Office = 55% of total | U40: Highest-priority facility
C43: Recent movement | L43: =TEXT($N$99,"mmm")&" vs "&TEXT($M$99,"mmm")&": "&IFERROR(IF(($N$100+$N$101)>($M$100+$M$101),"▲ ","▼ ")&TEXT(ABS((($N$100+$N$101)/($M$100+$M$101))-1),"0.0%"),"—") -> Dec vs Nov: ▲ 14.8% | U43: =IFERROR(IF(($N$100+$N$101)>($M$100+$M$101),"Increase","Decrease")&" driven mainly by "&$T$83,"—") -> Increase driven mainly by Scope 1
C46: Reduction focus | L46: =$M$89&" = "&TEXT($M$90,"#,##0")&" tCO₂e" -> Natural gas (stationary) = 463 tCO₂e | U46: =_xlfn.XLOOKUP($M$89,$H$65:$H$67,$I$65:$I$67,"Review emission drivers")&" "&LOWER(_xlfn.XLOOKUP($M$89,$H$65:$H$67,$J$65:$J$67,"efficiency review")) -> Stationary combustion efficiency + fuel mix
C49: ="Live from Scope 1 and Scope 2 tables • Reporting year "&$M$97 -> Live from Scope 1 and Scope 2 tables • Reporting year 2026
B52: ="All company, facility and activity data is fictional sample data. Emission factors: ECCC Emission Factors and Reference Values v3.0 (Oct 2025), for calendar year "&$M$97&". Location based Scope 2." -> All company, facility and activity data is fictional sample data. Emission factors: ECCC Emission Factors and Reference Values v3.0 (Oct 2025), for calendar year 2026. Location based Scope 2.
B53: Single-year reporting template. For a year-on-year comparison-ready version, contact Reiniel Celgie Chan.
B60: Dashboard chart and KPI data
B61: Calculated from the Scope 1 and Scope 2 worksheets. These cells feed the cards, charts and insight text on the dashboard canvas above.
B63: Scope 1 emissions by source — sorted low to high (for chart) | H63: Management focus lookup (small reference table)
B64: Source | C64: tCO₂e | D64: % of Scope 1 | E64: Chart axis label | H64: Source label | I64: Management focus | J64: Signal text
B65: {=_xlfn.LET(_xlpm.fuel,tblScope1[Activity / Fuel],_xlpm.src,tblScope1[Emission Source],_xlpm.amt,tblScope1[tCO₂e],_xlpm.combos,_xlfn.UNIQUE(_xlfn.HSTACK(_xlpm.src,_xlpm.fuel)),_xlpm.cat,INDEX(_xlpm.combos,0,1),_xlpm.fl,INDEX(_xlpm.combos,0,2),_xlpm.vals,SUMIFS(_xlpm.amt,_xlpm.src,_xlpm.cat,_xlpm.fuel,_xlpm.fl),_xlpm.labels,_xlpm.fl&" ("&LOWER(LEFT(_xlpm.cat,IFERROR(FIND(" ",_xlpm.cat)-1,LEN(_xlpm.cat))))&")",_xlfn.SORTBY(_xlpm.labels,_xlpm.vals,1))} -> Diesel (mobile) | C65: {=_xlfn.LET(_xlpm.fuel,tblScope1[Activity / Fuel],_xlpm.src,tblScope1[Emission Source],_xlpm.amt,tblScope1[tCO₂e],_xlpm.combos,_xlfn.UNIQUE(_xlfn.HSTACK(_xlpm.src,_xlpm.fuel)),_xlpm.cat,INDEX(_xlpm.combos,0,1),_xlpm.fl,INDEX(_xlpm.combos,0,2),_xlpm.vals,SUMIFS(_xlpm.amt,_xlpm.src,_xlpm.cat,_xlpm.fuel,_xlpm.fl),_xlfn.SORTBY(_xlpm.vals,_xlpm.vals,1))} -> 76.448668 | D65: {=_xlfn.LET(_xlpm.fuel,tblScope1[Activity / Fuel],_xlpm.src,tblScope1[Emission Source],_xlpm.amt,tblScope1[tCO₂e],_xlpm.combos,_xlfn.UNIQUE(_xlfn.HSTACK(_xlpm.src,_xlpm.fuel)),_xlpm.cat,INDEX(_xlpm.combos,0,1),_xlpm.fl,INDEX(_xlpm.combos,0,2),_xlpm.vals,SUMIFS(_xlpm.amt,_xlpm.src,_xlpm.cat,_xlpm.fuel,_xlpm.fl),_xlpm.pct,IFERROR(_xlpm.vals/SUM(_xlpm.vals),0),_xlfn.SORTBY(_xlpm.pct,_xlpm.vals,1))} -> 0.11249804 | E65: {=_xlfn.LET(_xlpm.fuel,tblScope1[Activity / Fuel],_xlpm.src,tblScope1[Emission Source],_xlpm.amt,tblScope1[tCO₂e],_xlpm.combos,_xlfn.UNIQUE(_xlfn.HSTACK(_xlpm.src,_xlpm.fuel)),_xlpm.cat,INDEX(_xlpm.combos,0,1),_xlpm.fl,INDEX(_xlpm.combos,0,2),_xlpm.vals,SUMIFS(_xlpm.amt,_xlpm.src,_xlpm.cat,_xlpm.fuel,_xlpm.fl),_xlpm.labels,_xlpm.fl&" ("&LOWER(LEFT(_xlpm.cat,IFERROR(FIND(" ",_xlpm.cat)-1,LEN(_xlpm.cat))))&")",_xlpm.pct,IFERROR(_xlpm.vals/SUM(_xlpm.vals),0),_xlfn.SORTBY(_xlpm.labels&" · "&TEXT(_xlpm.pct,"0.0%"),_xlpm.vals,1))} -> Diesel (mobile) · 11.2% | H65: Natural gas (stationary) | I65: Stationary combustion | J65: Efficiency + fuel mix
B66: Motor gasoline (mobile) | C66: 139.90149 | D66: 0.20587204 | E66: Motor gasoline (mobile) · 20.6% | H66: Motor gasoline (mobile) | I66: Fleet transition | J66: Efficiency + electrify
B67: Natural gas (stationary) | C67: 463.20542 | D67: 0.68162993 | E67: Natural gas (stationary) · 68.2% | H67: Diesel (mobile) | I67: Diesel reduction | J67: Efficiency + fuel switch
H68: Fallback (unmapped source): "Review emission drivers" / "Efficiency review"
B72: Facility totals — sorted low to high (for chart)
B73: Facility | C73: Scope 1 (tCO₂e) | D73: Scope 2 (tCO₂e) | E73: Total (tCO₂e) | F73: Province
B74: {=_xlfn.LET(_xlpm.facilities,_xlfn.UNIQUE(_xlfn.VSTACK(tblScope1[Facility],tblScope2[Facility])),_xlpm.scope1amt,SUMIFS(tblScope1[tCO₂e],tblScope1[Facility],_xlpm.facilities),_xlpm.scope2amt,SUMIFS(tblScope2[tCO₂e],tblScope2[Facility],_xlpm.facilities),_xlpm.totamt,_xlpm.scope1amt+_xlpm.scope2amt,_xlfn.SORTBY(_xlpm.facilities,_xlpm.totamt,1))} -> Vancouver Office | C74: {=_xlfn.LET(_xlpm.facilities,_xlfn.UNIQUE(_xlfn.VSTACK(tblScope1[Facility],tblScope2[Facility])),_xlpm.scope1amt,SUMIFS(tblScope1[tCO₂e],tblScope1[Facility],_xlpm.facilities),_xlpm.scope2amt,SUMIFS(tblScope2[tCO₂e],tblScope2[Facility],_xlpm.facilities),_xlpm.totamt,_xlpm.scope1amt+_xlpm.scope2amt,_xlfn.SORTBY(_xlpm.scope1amt,_xlpm.totamt,1))} -> 132.09201 | D74: {=_xlfn.LET(_xlpm.facilities,_xlfn.UNIQUE(_xlfn.VSTACK(tblScope1[Facility],tblScope2[Facility])),_xlpm.scope1amt,SUMIFS(tblScope1[tCO₂e],tblScope1[Facility],_xlpm.facilities),_xlpm.scope2amt,SUMIFS(tblScope2[tCO₂e],tblScope2[Facility],_xlpm.facilities),_xlpm.totamt,_xlpm.scope1amt+_xlpm.scope2amt,_xlfn.SORTBY(_xlpm.scope2amt,_xlpm.totamt,1))} -> 7.632 | E74: {=_xlfn.LET(_xlpm.facilities,_xlfn.UNIQUE(_xlfn.VSTACK(tblScope1[Facility],tblScope2[Facility])),_xlpm.scope1amt,SUMIFS(tblScope1[tCO₂e],tblScope1[Facility],_xlpm.facilities),_xlpm.scope2amt,SUMIFS(tblScope2[tCO₂e],tblScope2[Facility],_xlpm.facilities),_xlpm.totamt,_xlpm.scope1amt+_xlpm.scope2amt,_xlfn.SORTBY(_xlpm.totamt,_xlpm.totamt,1))} -> 139.72401 | F74: {=_xlfn.LET(_xlpm.facilities,_xlfn.UNIQUE(_xlfn.VSTACK(tblScope1[Facility],tblScope2[Facility])),_xlpm.scope1amt,SUMIFS(tblScope1[tCO₂e],tblScope1[Facility],_xlpm.facilities),_xlpm.scope2amt,SUMIFS(tblScope2[tCO₂e],tblScope2[Facility],_xlpm.facilities),_xlpm.totamt,_xlpm.scope1amt+_xlpm.scope2amt,_xlpm.prov,_xlfn.XLOOKUP(_xlpm.facilities,tblScope2[Facility],tblScope2[Province],_xlfn.XLOOKUP(_xlpm.facilities,tblScope1[Facility],tblScope1[Province],"")),_xlfn.SORTBY(_xlpm.prov,_xlpm.totamt,1))} -> British Columbia
B75: Toronto Office | C75: 260.71981 | D75: 48.203 | E75: 308.92281 | F75: Ontario
B76: Calgary Office | C76: 286.74376 | D76: 271.122 | E76: 557.86576 | F76: Alberta
B81: KPI and insight helper cells | R81: Peak Emission Month helper cells
B82: Total Scope 1 (tCO₂e) | M82: =SUM(tblScope1[tCO₂e]) -> 679.55558 | P82: tCO₂e | Scope 1 + Scope 2 | R82: Peak month (name) | S82: {=IFERROR(TEXT(INDEX($C$99:$N$99,MATCH(MAX($C$100:$N$100+$C$101:$N$101),$C$100:$N$100+$C$101:$N$101,0)),"mmmm"),"—")} -> January | T82: Main contributor to monthly movement
B83: Total Scope 2 (tCO₂e) | M83: =SUM(tblScope2[tCO₂e]) -> 326.957 | P83: ="tCO₂e | "&TEXT(M85,"0.0%")&" of total" -> tCO₂e | 67.5% of total | R83: Peak month emissions (tCO₂e) | S83: {=MAX($C$100:$N$100+$C$101:$N$101)} -> 117.79446 | T83: =IF(ABS(N100-M100)>=ABS(N101-M101),"Scope 1","Scope 2") -> Scope 1
B84: Total emissions (tCO₂e) | M84: =M82+M83 -> 1006.5126 | P84: ="tCO₂e | "&TEXT(M86,"0.0%")&" of total" -> tCO₂e | 32.5% of total | R84: Monthly average emissions (tCO₂e) | S84: {=AVERAGE($C$100:$N$100+$C$101:$N$101)} -> 83.876049
B85: Scope 1 share of total | M85: =IFERROR(M82/M84,0) -> 0.67515856 | P85: =TEXT(M90,"#,##0")&" tCO₂e | "&TEXT(M91,"0%")&" of total" -> 463 tCO₂e | 46% of total | R85: Peak vs monthly average | S85: =IFERROR(S83/S84-1,0) -> 0.40438728
B86: Scope 2 share of total | M86: =IFERROR(M83/M84,0) -> 0.32484144 | P86: =TEXT($S$83,"#,##0.0")&" tCO₂e | "&TEXT($S$85,"0%")&" above avg" -> 117.8 tCO₂e | 40% above avg
B87: Largest emitting facility | M87: {=INDEX(_xlfn.ANCHORARRAY($B$74),ROWS(_xlfn.ANCHORARRAY($B$74)))} -> Calgary Office
B88: Largest facility emissions (tCO₂e) | M88: {=INDEX(_xlfn.ANCHORARRAY($E$74),ROWS(_xlfn.ANCHORARRAY($E$74)))} -> 557.86576
B89: Largest Scope 1 source | M89: {=INDEX(_xlfn.ANCHORARRAY($B$65),ROWS(_xlfn.ANCHORARRAY($B$65)))} -> Natural gas (stationary)
B90: Largest Scope 1 source (tCO₂e) | M90: {=INDEX(_xlfn.ANCHORARRAY($C$65),ROWS(_xlfn.ANCHORARRAY($C$65)))} -> 463.20542
B91: Largest Scope 1 source, % of total emissions (for KPI 4) | M91: =IFERROR(M90/M84,0) -> 0.46020828
B92: Highest Scope 2 facility | M92: =INDEX(_xlfn.ANCHORARRAY($B$74),MATCH(MAX(_xlfn.ANCHORARRAY($D$74)),_xlfn.ANCHORARRAY($D$74),0)) -> Calgary Office
B93: Highest Scope 2 facility (tCO₂e) | M93: =MAX(_xlfn.ANCHORARRAY($D$74)) -> 271.122
B94: Highest Scope 2 facility, % of Scope 2 | M94: =IFERROR(M93/M83,0) -> 0.82922831
B95: Grid intensity at that facility (g CO₂e/kWh) | M95: {=_xlfn.LET(_xlpm.hotidx,MATCH(MAX(_xlfn.ANCHORARRAY($D$74)),_xlfn.ANCHORARRAY($D$74),0),_xlpm.hotprov,INDEX(_xlfn.ANCHORARRAY($F$74),_xlpm.hotidx),_xlfn.XLOOKUP(_xlpm.hotprov,_xlfn._xlws.FILTER(tblEF[Province / Territory],tblEF[Scope]="Scope 2"),_xlfn._xlws.FILTER(tblEF[Published CO₂e EF],tblEF[Scope]="Scope 2")))} -> 438
...

Sheet Scope 1
B2: Scope 1: Direct Emissions
B3: Sample activity data for a fictional organization. Cells with a cream background and blue text are inputs you can change. Every other cell is a formula.
B5: Record ID | C5: Date | D5: Facility | E5: Province | F5: Emission Source | G5: Activity / Fuel | H5: Activity Data | I5: Unit | J5: EF ID | K5: Aggregated Emission Factor | L5: EF Unit | M5: kg CO₂e | N5: tCO₂e | O5: Data Source / Evidence | P5: Notes
B6: S1-001 | C6: 46053 | D6: Toronto Office | E6: Ontario | F6: Stationary combustion | G6: Natural gas | H6: 16380 | I6: m³ | J6: EF-S1-NG-ON | K6: =_xlfn.XLOOKUP(tblScope1[[#This Row],[EF ID]],tblEF[EF ID],tblEF[Aggregated EF],"To check",0) -> 1.931311 | L6: =_xlfn.XLOOKUP(tblScope1[[#This Row],[EF ID]],tblEF[EF ID],tblEF[Aggregated EF Unit],"To check",0) -> kg CO₂e/m³ | M6: =IF(ISNUMBER($K6),$H6*$K6,"Check EF ID") -> 31634.874 | N6: =IF(ISNUMBER($M6),$M6/1000,"Check EF ID") -> 31.634874 | O6: Gas utility invoice (sample), January 2026 | P6: Building heating, marketable natural gas.
B7: S1-002 | C7: 46081 | D7: Toronto Office | E7: Ontario | F7: Stationary combustion | G7: Natural gas | H7: 14700 | I7: m³ | J7: EF-S1-NG-ON | K7: =_xlfn.XLOOKUP(tblScope1[[#This Row],[EF ID]],tblEF[EF ID],tblEF[Aggregated EF],"To check",0) -> 1.931311 | L7: =_xlfn.XLOOKUP(tblScope1[[#This Row],[EF ID]],tblEF[EF ID],tblEF[Aggregated EF Unit],"To check",0) -> kg CO₂e/m³ | M7: =IF(ISNUMBER($K7),$H7*$K7,"Check EF ID") -> 28390.272 | N7: =IF(ISNUMBER($M7),$M7/1000,"Check EF ID") -> 28.390272 | O7: Gas utility invoice (sample), February 2026 | P7: Building heating, marketable natural gas.
B8: S1-003 | C8: 46112 | D8: Toronto Office | E8: Ontario | F8: Stationary combustion | G8: Natural gas | H8: 10920 | I8: m³ | J8: EF-S1-NG-ON | K8: =_xlfn.XLOOKUP(tblScope1[[#This Row],[EF ID]],tblEF[EF ID],tblEF[Aggregated EF],"To check",0) -> 1.931311 | L8: =_xlfn.XLOOKUP(tblScope1[[#This Row],[EF ID]],tblEF[EF ID],tblEF[Aggregated EF Unit],"To check",0) -> kg CO₂e/m³ | M8: =IF(ISNUMBER($K8),$H8*$K8,"Check EF ID") -> 21089.916 | N8: =IF(ISNUMBER($M8),$M8/1000,"Check EF ID") -> 21.089916 | O8: Gas utility invoice (sample), March 2026 | P8: Building heating, marketable natural gas.
B9: S1-004 | C9: 46142 | D9: Toronto Office | E9: Ontario | F9: Stationary combustion | G9: Natural gas | H9: 8510 | I9: m³ | J9: EF-S1-NG-ON | K9: =_xlfn.XLOOKUP(tblScope1[[#This Row],[EF ID]],tblEF[EF ID],tblEF[Aggregated EF],"To check",0) -> 1.931311 | L9: =_xlfn.XLOOKUP(tblScope1[[#This Row],[EF ID]],tblEF[EF ID],tblEF[Aggregated EF Unit],"To check",0) -> kg CO₂e/m³ | M9: =IF(ISNUMBER($K9),$H9*$K9,"Check EF ID") -> 16435.457 | N9: =IF(ISNUMBER($M9),$M9/1000,"Check EF ID") -> 16.435457 | O9: Gas utility invoice (sample), April 2026 | P9: Building heating, marketable natural gas.
B10: S1-005 | C10: 46173 | D10: Toronto Office | E10: Ontario | F10: Stationary combustion | G10: Natural gas | H10: 6100 | I10: m³ | J10: EF-S1-NG-ON | K10: =_xlfn.XLOOKUP(tblScope1[[#This Row],[EF ID]],tblEF[EF ID],tblEF[Aggregated EF],"To check",0) -> 1.931311 | L10: =_xlfn.XLOOKUP(tblScope1[[#This Row],[EF ID]],tblEF[EF ID],tblEF[Aggregated EF Unit],"To check",0) -> kg CO₂e/m³ | M10: =IF(ISNUMBER($K10),$H10*$K10,"Check EF ID") -> 11780.997 | N10: =IF(ISNUMBER($M10),$M10/1000,"Check EF ID") -> 11.780997 | O10: Gas utility invoice (sample), May 2026 | P10: Building heating, marketable natural gas.
B11: S1-006 | C11: 46203 | D11: Toronto Office | E11: Ontario | F11: Stationary combustion | G11: Natural gas | H11: 3880 | I11: m³ | J11: EF-S1-NG-ON | K11: =_xlfn.XLOOKUP(tblScope1[[#This Row],[EF ID]],tblEF[EF ID],tblEF[Aggregated EF],"To check",0) -> 1.931311 | L11: =_xlfn.XLOOKUP(tblScope1[[#This Row],[EF ID]],tblEF[EF ID],tblEF[Aggregated EF Unit],"To check",0) -> kg CO₂e/m³ | M11: =IF(ISNUMBER($K11),$H11*$K11,"Check EF ID") -> 7493.4867 | N11: =IF(ISNUMBER($M11),$M11/1000,"Check EF ID") -> 7.4934867 | O11: Gas utility invoice (sample), June 2026 | P11: Building heating, marketable natural gas.
B12: S1-007 | C12: 46234 | D12: Toronto Office | E12: Ontario | F12: Stationary combustion | G12: Natural gas | H12: 1860 | I12: m³ | J12: EF-S1-NG-ON | K12: =_xlfn.XLOOKUP(tblScope1[[#This Row],[EF ID]],tblEF[EF ID],tblEF[Aggregated EF],"To check",0) -> 1.931311 | L12: =_xlfn.XLOOKUP(tblScope1[[#This Row],[EF ID]],tblEF[EF ID],tblEF[Aggregated EF Unit],"To check",0) -> kg CO₂e/m³ | M12: =IF(ISNUMBER($K12),$H12*$K12,"Check EF ID") -> 3592.2385 | N12: =IF(ISNUMBER($M12),$M12/1000,"Check EF ID") -> 3.5922385 | O12: Gas utility invoice (sample), July 2026 | P12: Building heating, marketable natural gas.
B13: S1-008 | C13: 46265 | D13: Toronto Office | E13: Ontario | F13: Stationary combustion | G13: Natural gas | H13: 1980 | I13: m³ | J13: EF-S1-NG-ON | K13: =_xlfn.XLOOKUP(tblScope1[[#This Row],[EF ID]],tblEF[EF ID],tblEF[Aggregated EF],"To check",0) -> 1.931311 | L13: =_xlfn.XLOOKUP(tblScope1[[#This Row],[EF ID]],tblEF[EF ID],tblEF[Aggregated EF Unit],"To check",0) -> kg CO₂e/m³ | M13: =IF(ISNUMBER($K13),$H13*$K13,"Check EF ID") -> 3823.9958 | N13: =IF(ISNUMBER($M13),$M13/1000,"Check EF ID") -> 3.8239958 | O13: Gas utility invoice (sample), August 2026 | P13: Building heating, marketable natural gas.
B14: S1-009 | C14: 46295 | D14: Toronto Office | E14: Ontario | F14: Stationary combustion | G14: Natural gas | H14: 2360 | I14: m³ | J14: EF-S1-NG-ON | K14: =_xlfn.XLOOKUP(tblScope1[[#This Row],[EF ID]],tblEF[EF ID],tblEF[Aggregated EF],"To check",0) -> 1.931311 | L14: =_xlfn.XLOOKUP(tblScope1[[#This Row],[EF ID]],tblEF[EF ID],tblEF[Aggregated EF Unit],"To check",0) -> kg CO₂e/m³ | M14: =IF(ISNUMBER($K14),$H14*$K14,"Check EF ID") -> 4557.894 | N14: =IF(ISNUMBER($M14),$M14/1000,"Check EF ID") -> 4.557894 | O14: Gas utility invoice (sample), September 2026 | P14: Building heating, marketable natural gas.
B15: S1-010 | C15: 46326 | D15: Toronto Office | E15: Ontario | F15: Stationary combustion | G15: Natural gas | H15: 6910 | I15: m³ | J15: EF-S1-NG-ON | K15: =_xlfn.XLOOKUP(tblScope1[[#This Row],[EF ID]],tblEF[EF ID],tblEF[Aggregated EF],"To check",0) -> 1.931311 | L15: =_xlfn.XLOOKUP(tblScope1[[#This Row],[EF ID]],tblEF[EF ID],tblEF[Aggregated EF Unit],"To check",0) -> kg CO₂e/m³ | M15: =IF(ISNUMBER($K15),$H15*$K15,"Check EF ID") -> 13345.359 | N15: =IF(ISNUMBER($M15),$M15/1000,"Check EF ID") -> 13.345359 | O15: Gas utility invoice (sample), October 2026 | P15: Building heating, marketable natural gas.
B16: S1-011 | C16: 46356 | D16: Toronto Office | E16: Ontario | F16: Stationary combustion | G16: Natural gas | H16: 10680 | I16: m³ | J16: EF-S1-NG-ON | K16: =_xlfn.XLOOKUP(tblScope1[[#This Row],[EF ID]],tblEF[EF ID],tblEF[Aggregated EF],"To check",0) -> 1.931311 | L16: =_xlfn.XLOOKUP(tblScope1[[#This Row],[EF ID]],tblEF[EF ID],tblEF[Aggregated EF Unit],"To check",0) -> kg CO₂e/m³ | M16: =IF(ISNUMBER($K16),$H16*$K16,"Check EF ID") -> 20626.401 | N16: =IF(ISNUMBER($M16),$M16/1000,"Check EF ID") -> 20.626401 | O16: Gas utility invoice (sample), November 2026 | P16: Building heating, marketable natural gas.
B17: S1-012 | C17: 46387 | D17: Toronto Office | E17: Ontario | F17: Stationary combustion | G17: Natural gas | H17: 13820 | I17: m³ | J17: EF-S1-NG-ON | K17: =_xlfn.XLOOKUP(tblScope1[[#This Row],[EF ID]],tblEF[EF ID],tblEF[Aggregated EF],"To check",0) -> 1.931311 | L17: =_xlfn.XLOOKUP(tblScope1[[#This Row],[EF ID]],tblEF[EF ID],tblEF[Aggregated EF Unit],"To check",0) -> kg CO₂e/m³ | M17: =IF(ISNUMBER($K17),$H17*$K17,"Check EF ID") -> 26690.718 | N17: =IF(ISNUMBER($M17),$M17/1000,"Check EF ID") -> 26.690718 | O17: Gas utility invoice (sample), December 2026 | P17: Building heating, marketable natural gas.
... B101: S1-096 | C101: 46387 | D101: Vancouver Office | E101: British Columbia | F101: Mobile combustion | G101: Motor gasoline | H101: 1040 | I101: L | J101: EF-S1-GAS | K101: =_xlfn.XLOOKUP(tblScope1[[#This Row],[EF ID]],tblEF[EF ID],tblEF[Aggregated EF],"To check",0) -> 2.3151 | L101: =_xlfn.XLOOKUP(tblScope1[[#This Row],[EF ID]],tblEF[EF ID],tblEF[Aggregated EF Unit],"To check",0) -> kg CO₂e/L | M101: =IF(ISNUMBER($K101),$H101*$K101,"Check EF ID") -> 2407.704 | N101: =IF(ISNUMBER($M101),$M101/1000,"Check EF ID") -> 2.407704 | O101: Fleet fuel card statement (sample), December 2026 | P101: Company owned passenger vehicles. No diesel vehicles at this site.
B102: TOTAL SCOPE 1 | M102: =SUM(M6:M101) -> 679555.58 | N102: =SUM(N6:N101) -> 679.55558 | O102: kg CO₂e and tCO₂e
B104: Legend and method
B105: Input cells | C105: Activity Data in column H. Replace these with your own metered or invoiced quantities. Everything else recalculates.
B106: Formula cells | C106: Columns K, L, M and N. Emission factors are pulled from the Emission Factors DB sheet by EF ID, never typed in by hand.
B107: Calculation | C107: kg CO₂e = Activity Data x Aggregated EF. tCO₂e = kg CO₂e / 1,000.
B108: Sample data | C108: All company names, facilities and activity quantities on this sheet are fictional and are included to demonstrate the calculation method.
B110: Sum of tCO₂e | C110: Column Labels
B111: Row Labels | C111: Calgary Office | D111: Toronto Office | E111: Vancouver Office | F111: Grand Total
B112: Jan | C112: 37.525031 | D112: 37.417769 | E112: 19.025656 | F112: 93.968456
B113: Feb | C113: 34.329226 | D113: 34.003632 | E113: 17.256575 | F113: 85.589433
B114: Mar | C114: 27.800877 | D114: 26.703276 | E114: 13.442295 | F114: 67.946448
B115: Apr | C115: 24.624156 | D115: 22.275871 | E115: 11.482924 | F115: 58.382951
B116: May | C116: 20.89781 | D116: 17.987372 | E116: 9.1153025 | F116: 48.000485
B117: Jun | C117: 16.894019 | D117: 13.699862 | E117: 6.8030187 | F117: 37.396899
B118: Jul | C118: 13.310774 | D118: 10.014451 | E118: 4.9588379 | F118: 28.284063
B119: Aug | C119: 13.824236 | D119: 10.415744 | E119: 5.1666327 | F119: 29.406612
B120: Sep | C120: 14.158868 | D120: 10.980107 | E120: 5.5319681 | F120: 30.670942
B121: Oct | C121: 21.566946 | D121: 18.978131 | E121: 9.5128242 | F121: 50.057901
B122: Nov | C122: 28.085506 | D122: 26.089638 | E122: 13.297178 | F122: 67.472321
B123: Dec | C123: 33.726315 | D123: 32.153955 | E123: 16.498801 | F123: 82.379071
B124: Grand Total | C124: 286.74376 | D124: 260.71981 | E124: 132.09201 | F124: 679.55558

Sheet Scope 2
B2: Scope 2: Purchased Electricity (location based)
B3: Location based method only. Provincial electricity consumption intensities come from ECCC Table 5.3 for 2026. No market based factors or renewable energy certificates are used in this workbook.
B5: Record ID | C5: Date | D5: Facility | E5: Province | F5: Electricity Consumption | G5: Unit | H5: EF ID | I5: Electricity Emission Factor | J5: EF Unit | K5: kg CO₂e | L5: tCO₂e | M5: Data Source / Evidence | N5: Notes
B6: S2-001 | C6: 46053 | D6: Toronto Office | E6: Ontario | F6: 60000 | G6: kWh | H6: EF-S2-ELEC-ON | I6: =_xlfn.XLOOKUP(tblScope2[[#This Row],[EF ID]],tblEF[EF ID],tblEF[Aggregated EF],"To check",0) -> 0.059 | J6: =_xlfn.XLOOKUP(tblScope2[[#This Row],[EF ID]],tblEF[EF ID],tblEF[Aggregated EF Unit],"To check",0) -> kg CO₂e/kWh | K6: =IF(ISNUMBER($I6),$F6*$I6,"Check EF ID") -> 3540 | L6: =IF(ISNUMBER($K6),$K6/1000,"Check EF ID") -> 3.54 | M6: Electricity utility invoice (sample), January 2026 | N6: Ontario grid intensity is low because of nuclear and hydro generation.
B7: S2-002 | C7: 46081 | D7: Toronto Office | E7: Ontario | F7: 61000 | G7: kWh | H7: EF-S2-ELEC-ON | I7: =_xlfn.XLOOKUP(tblScope2[[#This Row],[EF ID]],tblEF[EF ID],tblEF[Aggregated EF],"To check",0) -> 0.059 | J7: =_xlfn.XLOOKUP(tblScope2[[#This Row],[EF ID]],tblEF[EF ID],tblEF[Aggregated EF Unit],"To check",0) -> kg CO₂e/kWh | K7: =IF(ISNUMBER($I7),$F7*$I7,"Check EF ID") -> 3599 | L7: =IF(ISNUMBER($K7),$K7/1000,"Check EF ID") -> 3.599 | M7: Electricity utility invoice (sample), February 2026 | N7: Ontario grid intensity is low because of nuclear and hydro generation.
B8: S2-003 | C8: 46112 | D8: Toronto Office | E8: Ontario | F8: 65000 | G8: kWh | H8: EF-S2-ELEC-ON | I8: =_xlfn.XLOOKUP(tblScope2[[#This Row],[EF ID]],tblEF[EF ID],tblEF[Aggregated EF],"To check",0) -> 0.059 | J8: =_xlfn.XLOOKUP(tblScope2[[#This Row],[EF ID]],tblEF[EF ID],tblEF[Aggregated EF Unit],"To check",0) -> kg CO₂e/kWh | K8: =IF(ISNUMBER($I8),$F8*$I8,"Check EF ID") -> 3835 | L8: =IF(ISNUMBER($K8),$K8/1000,"Check EF ID") -> 3.835 | M8: Electricity utility invoice (sample), March 2026 | N8: Ontario grid intensity is low because of nuclear and hydro generation.
B9: S2-004 | C9: 46142 | D9: Toronto Office | E9: Ontario | F9: 66000 | G9: kWh | H9: EF-S2-ELEC-ON | I9: =_xlfn.XLOOKUP(tblScope2[[#This Row],[EF ID]],tblEF[EF ID],tblEF[Aggregated EF],"To check",0) -> 0.059 | J9: =_xlfn.XLOOKUP(tblScope2[[#This Row],[EF ID]],tblEF[EF ID],tblEF[Aggregated EF Unit],"To check",0) -> kg CO₂e/kWh | K9: =IF(ISNUMBER($I9),$F9*$I9,"Check EF ID") -> 3894 | L9: =IF(ISNUMBER($K9),$K9/1000,"Check EF ID") -> 3.894 | M9: Electricity utility invoice (sample), April 2026 | N9: Ontario grid intensity is low because of nuclear and hydro generation.
B10: S2-005 | C10: 46173 | D10: Toronto Office | E10: Ontario | F10: 67000 | G10: kWh | H10: EF-S2-ELEC-ON | I10: =_xlfn.XLOOKUP(tblScope2[[#This Row],[EF ID]],tblEF[EF ID],tblEF[Aggregated EF],"To check",0) -> 0.059 | J10: =_xlfn.XLOOKUP(tblScope2[[#This Row],[EF ID]],tblEF[EF ID],tblEF[Aggregated EF Unit],"To check",0) -> kg CO₂e/kWh | K10: =IF(ISNUMBER($I10),$F10*$I10,"Check EF ID") -> 3953 | L10: =IF(ISNUMBER($K10),$K10/1000,"Check EF ID") -> 3.953 | M10: Electricity utility invoice (sample), May 2026 | N10: Ontario grid intensity is low because of nuclear and hydro generation.
B11: S2-006 | C11: 46203 | D11: Toronto Office | E11: Ontario | F11: 68000 | G11: kWh | H11: EF-S2-ELEC-ON | I11: =_xlfn.XLOOKUP(tblScope2[[#This Row],[EF ID]],tblEF[EF ID],tblEF[Aggregated EF],"To check",0) -> 0.059 | J11: =_xlfn.XLOOKUP(tblScope2[[#This Row],[EF ID]],tblEF[EF ID],tblEF[Aggregated EF Unit],"To check",0) -> kg CO₂e/kWh | K11: =IF(ISNUMBER($I11),$F11*$I11,"Check EF ID") -> 4012 | L11: =IF(ISNUMBER($K11),$K11/1000,"Check EF ID") -> 4.012 | M11: Electricity utility invoice (sample), June 2026 | N11: Ontario grid intensity is low because of nuclear and hydro generation.
B12: S2-007 | C12: 46234 | D12: Toronto Office | E12: Ontario | F12: 76000 | G12: kWh | H12: EF-S2-ELEC-ON | I12: =_xlfn.XLOOKUP(tblScope2[[#This Row],[EF ID]],tblEF[EF ID],tblEF[Aggregated EF],"To check",0) -> 0.059 | J12: =_xlfn.XLOOKUP(tblScope2[[#This Row],[EF ID]],tblEF[EF ID],tblEF[Aggregated EF Unit],"To check",0) -> kg CO₂e/kWh | K12: =IF(ISNUMBER($I12),$F12*$I12,"Check EF ID") -> 4484 | L12: =IF(ISNUMBER($K12),$K12/1000,"Check EF ID") -> 4.484 | M12: Electricity utility invoice (sample), July 2026 | N12: Ontario grid intensity is low because of nuclear and hydro generation.
B13: S2-008 | C13: 46265 | D13: Toronto Office | E13: Ontario | F13: 80000 | G13: kWh | H13: EF-S2-ELEC-ON | I13: =_xlfn.XLOOKUP(tblScope2[[#This Row],[EF ID]],tblEF[EF ID],tblEF[Aggregated EF],"To check",0) -> 0.059 | J13: =_xlfn.XLOOKUP(tblScope2[[#This Row],[EF ID]],tblEF[EF ID],tblEF[Aggregated EF Unit],"To check",0) -> kg CO₂e/kWh | K13: =IF(ISNUMBER($I13),$F13*$I13,"Check EF ID") -> 4720 | L13: =IF(ISNUMBER($K13),$K13/1000,"Check EF ID") -> 4.72 | M13: Electricity utility invoice (sample), August 2026 | N13: Ontario grid intensity is low because of nuclear and hydro generation.
B14: S2-009 | C14: 46295 | D14: Toronto Office | E14: Ontario | F14: 82000 | G14: kWh | H14: EF-S2-ELEC-ON | I14: =_xlfn.XLOOKUP(tblScope2[[#This Row],[EF ID]],tblEF[EF ID],tblEF[Aggregated EF],"To check",0) -> 0.059 | J14: =_xlfn.XLOOKUP(tblScope2[[#This Row],[EF ID]],tblEF[EF ID],tblEF[Aggregated EF Unit],"To check",0) -> kg CO₂e/kWh | K14: =IF(ISNUMBER($I14),$F14*$I14,"Check EF ID") -> 4838 | L14: =IF(ISNUMBER($K14),$K14/1000,"Check EF ID") -> 4.838 | M14: Electricity utility invoice (sample), September 2026 | N14: Ontario grid intensity is low because of nuclear and hydro generation.
B15: S2-010 | C15: 46326 | D15: Toronto Office | E15: Ontario | F15: 67000 | G15: kWh | H15: EF-S2-ELEC-ON | I15: =_xlfn.XLOOKUP(tblScope2[[#This Row],[EF ID]],tblEF[EF ID],tblEF[Aggregated EF],"To check",0) -> 0.059 | J15: =_xlfn.XLOOKUP(tblScope2[[#This Row],[EF ID]],tblEF[EF ID],tblEF[Aggregated EF Unit],"To check",0) -> kg CO₂e/kWh | K15: =IF(ISNUMBER($I15),$F15*$I15,"Check EF ID") -> 3953 | L15: =IF(ISNUMBER($K15),$K15/1000,"Check EF ID") -> 3.953 | M15: Electricity utility invoice (sample), October 2026 | N15: Ontario grid intensity is low because of nuclear and hydro generation.
B16: S2-011 | C16: 46356 | D16: Toronto Office | E16: Ontario | F16: 64000 | G16: kWh | H16: EF-S2-ELEC-ON | I16: =_xlfn.XLOOKUP(tblScope2[[#This Row],[EF ID]],tblEF[EF ID],tblEF[Aggregated EF],"To check",0) -> 0.059 | J16: =_xlfn.XLOOKUP(tblScope2[[#This Row],[EF ID]],tblEF[EF ID],tblEF[Aggregated EF Unit],"To check",0) -> kg CO₂e/kWh | K16: =IF(ISNUMBER($I16),$F16*$I16,"Check EF ID") -> 3776 | L16: =IF(ISNUMBER($K16),$K16/1000,"Check EF ID") -> 3.776 | M16: Electricity utility invoice (sample), November 2026 | N16: Ontario grid intensity is low because of nuclear and hydro generation.
B17: S2-012 | C17: 46387 | D17: Toronto Office | E17: Ontario | F17: 61000 | G17: kWh | H17: EF-S2-ELEC-ON | I17: =_xlfn.XLOOKUP(tblScope2[[#This Row],[EF ID]],tblEF[EF ID],tblEF[Aggregated EF],"To check",0) -> 0.059 | J17: =_xlfn.XLOOKUP(tblScope2[[#This Row],[EF ID]],tblEF[EF ID],tblEF[Aggregated EF Unit],"To check",0) -> kg CO₂e/kWh | K17: =IF(ISNUMBER($I17),$F17*$I17,"Check EF ID") -> 3599 | L17: =IF(ISNUMBER($K17),$K17/1000,"Check EF ID") -> 3.599 | M17: Electricity utility invoice (sample), December 2026 | N17: Ontario grid intensity is low because of nuclear and hydro generation.
... B41: S2-036 | C41: 46387 | D41: Vancouver Office | E41: British Columbia | F41: 32000 | G41: kWh | H41: EF-S2-ELEC-BC | I41: =_xlfn.XLOOKUP(tblScope2[[#This Row],[EF ID]],tblEF[EF ID],tblEF[Aggregated EF],"To check",0) -> 0.018 | J41: =_xlfn.XLOOKUP(tblScope2[[#This Row],[EF ID]],tblEF[EF ID],tblEF[Aggregated EF Unit],"To check",0) -> kg CO₂e/kWh | K41: =IF(ISNUMBER($I41),$F41*$I41,"Check EF ID") -> 576 | L41: =IF(ISNUMBER($K41),$K41/1000,"Check EF ID") -> 0.576 | M41: Electricity utility invoice (sample), December 2026 | N41: British Columbia grid is almost entirely hydroelectric.
B42: TOTAL SCOPE 2 | K42: =SUM(K6:K41) -> 326957 | L42: =SUM(L6:L41) -> 326.957 | M42: kg CO₂e and tCO₂e
B44: Legend and method
B45: Input cells | C45: Electricity Consumption in column F. Replace with metered or invoiced kWh.
B46: Formula cells | C46: Columns I, J, K and L. Factors are looked up from the Emission Factors DB sheet by EF ID.
B47: Calculation | C47: kg CO₂e = kWh x kg CO₂e/kWh. tCO₂e = kg CO₂e / 1,000.
B48: Sample data | C48: All facilities and consumption figures on this sheet are fictional sample data.
B51: Sum of tCO₂e | C51: Column Labels
B52: Row Labels | C52: Calgary Office | D52: Toronto Office | E52: Vancouver Office | F52: Grand Total
B53: Jan | C53: 19.71 | D53: 3.54 | E53: 0.576 | F53: 23.826
B54: Feb | C54: 20.586 | D54: 3.599 | E54: 0.576 | F54: 24.761
B55: Mar | C55: 21.9 | D55: 3.835 | E55: 0.612 | F55: 26.347
B56: Apr | C56: 21.462 | D56: 3.894 | E56: 0.612 | F56: 25.968
B57: May | C57: 21.9 | D57: 3.953 | E57: 0.63 | F57: 26.483
B58: Jun | C58: 22.776 | D58: 4.012 | E58: 0.63 | F58: 27.418
B59: Jul | C59: 24.528 | D59: 4.484 | E59: 0.702 | F59: 29.714
B60: Aug | C60: 25.842 | D60: 4.72 | E60: 0.72 | F60: 31.282
B61: Sep | C61: 27.594 | D61: 4.838 | E61: 0.756 | F61: 33.188
B62: Oct | C62: 22.776 | D62: 3.953 | E62: 0.63 | F62: 27.359
B63: Nov | C63: 21.462 | D63: 3.776 | E63: 0.612 | F63: 25.85
B64: Dec | C64: 20.586 | D64: 3.599 | E64: 0.576 | F64: 24.761
B65: Grand Total | C65: 271.122 | D65: 48.203 | E65: 7.632 | F65: 326.957

Sheet Emission Factors DB
B2: Emission Factors Database
B3: Every factor used anywhere in this workbook is listed here with its official source. Scope 1 rows keep the individual CO₂, CH₄ and N₂O factors published by ECCC and calculate a combined CO₂e factor. Scope 2 rows use factors ECCC already publishes as CO₂e.
B5: EF ID | C5: Scope | D5: Emission Source | E5: Activity / Fuel | F5: Province / Territory | G5: Original EF Unit | H5: CO₂ EF | I5: CH₄ EF | J5: N₂O EF | K5: Published CO₂e EF | L5: CO₂ GWP | M5: CH₄ GWP | N5: N₂O GWP | O5: Aggregated EF | P5: Aggregated EF Unit | Q5: EF Basis | R5: Applicable Calendar Year | S5: Source Organization | T5: Source Document | U5: Source Table | V5: Source URL | W5: Notes
B6: EF-S1-NG-ON | C6: Scope 1 | D6: Stationary combustion | E6: Natural gas (marketable) | F6: Ontario | G6: g GHG/m³ | H6: 1921 | I6: 0.037 | J6: 0.035 | K6: n/a | L6: ='GWP Reference'!$D$6 -> 1 | M6: ='GWP Reference'!$D$7 -> 28 | N6: ='GWP Reference'!$D$8 -> 265 | O6: =IF(ISNUMBER($K6),$K6/1000,($H6*$L6+$I6*$M6+$J6*$N6)/1000) -> 1.931311 | P6: kg CO₂e/m³ | Q6: Calculated CO₂e factor from ECCC gas specific emission factors | R6: 2026 | S6: Environment and Climate Change Canada (ECCC) | T6: Emission Factors and Reference Values, Version 3.0, October 2025 | U6: Tables 1.3 and 2.3 | V6: https://www.canada.ca/en/environment-climate-change/services/climate-change/pricing-pollution-how-it-will-work/output-based-pricing-system/federal-greenhouse-gas-offset-system/emission-factors-reference-values.html | W6: CO₂ from Table 1.3 (marketable). CH₄ and N₂O from Table 2.3, Residential, Construction, Commercial/Institutional, Agriculture row, which is the closest published match for a commercial office building.
B7: EF-S1-NG-AB | C7: Scope 1 | D7: Stationary combustion | E7: Natural gas (marketable) | F7: Alberta | G7: g GHG/m³ | H7: 1962 | I7: 0.037 | J7: 0.035 | K7: n/a | L7: ='GWP Reference'!$D$6 -> 1 | M7: ='GWP Reference'!$D$7 -> 28 | N7: ='GWP Reference'!$D$8 -> 265 | O7: =IF(ISNUMBER($K7),$K7/1000,($H7*$L7+$I7*$M7+$J7*$N7)/1000) -> 1.972311 | P7: kg CO₂e/m³ | Q7: Calculated CO₂e factor from ECCC gas specific emission factors | R7: 2026 | S7: Environment and Climate Change Canada (ECCC) | T7: Emission Factors and Reference Values, Version 3.0, October 2025 | U7: Tables 1.3 and 2.3 | V7: https://www.canada.ca/en/environment-climate-change/services/climate-change/pricing-pollution-how-it-will-work/output-based-pricing-system/federal-greenhouse-gas-offset-system/emission-factors-reference-values.html | W7: CO₂ from Table 1.3 (marketable). CH₄ and N₂O from Table 2.3, Residential, Construction, Commercial/Institutional, Agriculture row.
B8: EF-S1-NG-BC | C8: Scope 1 | D8: Stationary combustion | E8: Natural gas (marketable) | F8: British Columbia | G8: g GHG/m³ | H8: 1966 | I8: 0.037 | J8: 0.035 | K8: n/a | L8: ='GWP Reference'!$D$6 -> 1 | M8: ='GWP Reference'!$D$7 -> 28 | N8: ='GWP Reference'!$D$8 -> 265 | O8: =IF(ISNUMBER($K8),$K8/1000,($H8*$L8+$I8*$M8+$J8*$N8)/1000) -> 1.976311 | P8: kg CO₂e/m³ | Q8: Calculated CO₂e factor from ECCC gas specific emission factors | R8: 2026 | S8: Environment and Climate Change Canada (ECCC) | T8: Emission Factors and Reference Values, Version 3.0, October 2025 | U8: Tables 1.3 and 2.3 | V8: https://www.canada.ca/en/environment-climate-change/services/climate-change/pricing-pollution-how-it-will-work/output-based-pricing-system/federal-greenhouse-gas-offset-system/emission-factors-reference-values.html | W8: CO₂ from Table 1.3 (marketable). CH₄ and N₂O from Table 2.3, Residential, Construction, Commercial/Institutional, Agriculture row.
B9: EF-S1-GAS | C9: Scope 1 | D9: Mobile combustion | E9: Motor gasoline | F9: Canada (all provinces) | G9: g GHG/L | H9: 2307 | I9: 0.1 | J9: 0.02 | K9: n/a | L9: ='GWP Reference'!$D$6 -> 1 | M9: ='GWP Reference'!$D$7 -> 28 | N9: ='GWP Reference'!$D$8 -> 265 | O9: =IF(ISNUMBER($K9),$K9/1000,($H9*$L9+$I9*$M9+$J9*$N9)/1000) -> 2.3151 | P9: kg CO₂e/L | Q9: Calculated CO₂e factor from ECCC gas specific emission factors | R9: 2026 | S9: Environment and Climate Change Canada (ECCC) | T9: Emission Factors and Reference Values, Version 3.0, October 2025 | U9: Table 4.3 | V9: https://www.canada.ca/en/environment-climate-change/services/climate-change/pricing-pollution-how-it-will-work/output-based-pricing-system/federal-greenhouse-gas-offset-system/emission-factors-reference-values.html | W9: Motor Gasoline row of Table 4.3. ECCC publishes a single national factor for this fuel, so the same factor applies at all three facilities.
B10: EF-S1-DSL | C10: Scope 1 | D10: Mobile combustion | E10: Diesel | F10: Canada (all provinces) | G10: g GHG/L | H10: 2681 | I10: 0.078 | J10: 0.022 | K10: n/a | L10: ='GWP Reference'!$D$6 -> 1 | M10: ='GWP Reference'!$D$7 -> 28 | N10: ='GWP Reference'!$D$8 -> 265 | O10: =IF(ISNUMBER($K10),$K10/1000,($H10*$L10+$I10*$M10+$J10*$N10)/1000) -> 2.689014 | P10: kg CO₂e/L | Q10: Simplified diesel proxy — user methodology selection required | R10: 2026 | S10: Environment and Climate Change Canada (ECCC) | T10: Emission Factors and Reference Values, Version 3.0, October 2025 | U10: Table 4.3 | V10: https://www.canada.ca/en/environment-climate-change/services/climate-change/pricing-pollution-how-it-will-work/output-based-pricing-system/federal-greenhouse-gas-offset-system/emission-factors-reference-values.html | W10: The current values are retained as a temporary simplified proxy and are not automatically conservative. Scope 1 describes these sources as company-owned light trucks. For a tailored inventory, use the latest ECCC National Inventory Report Annex 6 table for Light-duty Diesel Trucks and select the applicable emissions-control category shown in the source. Enter the selected published CO₂, CH₄ and N₂O factors in columns H to J; the aggregated CO₂e factor in column O will update automatically. If the control category is unknown, document the proxy selected and the reason for the selection.
B11: EF-S2-ELEC-ON | C11: Scope 2 | D11: Purchased electricity | E11: Grid electricity (location based) | F11: Ontario | G11: g CO₂e/kWh | H11: n/a | I11: n/a | J11: n/a | K11: 59 | L11: ='GWP Reference'!$D$6 -> 1 | M11: ='GWP Reference'!$D$7 -> 28 | N11: ='GWP Reference'!$D$8 -> 265 | O11: =IF(ISNUMBER($K11),$K11/1000,($H11*$L11+$I11*$M11+$J11*$N11)/1000) -> 0.059 | P11: kg CO₂e/kWh | Q11: Published by ECCC directly as CO₂e | R11: 2026 | S11: Environment and Climate Change Canada (ECCC) | T11: Emission Factors and Reference Values, Version 3.0, October 2025 | U11: Table 5.3 | V11: https://www.canada.ca/en/environment-climate-change/services/climate-change/pricing-pollution-how-it-will-work/output-based-pricing-system/federal-greenhouse-gas-offset-system/emission-factors-reference-values.html | W11: Electricity consumption intensity for 2026. Already a combined CO₂e value, so no GWP step is applied. Converted to kg by dividing by 1,000.
B12: EF-S2-ELEC-AB | C12: Scope 2 | D12: Purchased electricity | E12: Grid electricity (location based) | F12: Alberta | G12: g CO₂e/kWh | H12: n/a | I12: n/a | J12: n/a | K12: 438 | L12: ='GWP Reference'!$D$6 -> 1 | M12: ='GWP Reference'!$D$7 -> 28 | N12: ='GWP Reference'!$D$8 -> 265 | O12: =IF(ISNUMBER($K12),$K12/1000,($H12*$L12+$I12*$M12+$J12*$N12)/1000) -> 0.438 | P12: kg CO₂e/kWh | Q12: Published by ECCC directly as CO₂e | R12: 2026 | S12: Environment and Climate Change Canada (ECCC) | T12: Emission Factors and Reference Values, Version 3.0, October 2025 | U12: Table 5.3 | V12: https://www.canada.ca/en/environment-climate-change/services/climate-change/pricing-pollution-how-it-will-work/output-based-pricing-system/federal-greenhouse-gas-offset-system/emission-factors-reference-values.html | W12: Electricity consumption intensity for 2026. Already a combined CO₂e value, so no GWP step is applied. Converted to kg by dividing by 1,000.
B13: EF-S2-ELEC-BC | C13: Scope 2 | D13: Purchased electricity | E13: Grid electricity (location based) | F13: British Columbia | G13: g CO₂e/kWh | H13: n/a | I13: n/a | J13: n/a | K13: 18 | L13: ='GWP Reference'!$D$6 -> 1 | M13: ='GWP Reference'!$D$7 -> 28 | N13: ='GWP Reference'!$D$8 -> 265 | O13: =IF(ISNUMBER($K13),$K13/1000,($H13*$L13+$I13*$M13+$J13*$N13)/1000) -> 0.018 | P13: kg CO₂e/kWh | Q13: Published by ECCC directly as CO₂e | R13: 2026 | S13: Environment and Climate Change Canada (ECCC) | T13: Emission Factors and Reference Values, Version 3.0, October 2025 | U13: Table 5.3 | V13: https://www.canada.ca/en/environment-climate-change/services/climate-change/pricing-pollution-how-it-will-work/output-based-pricing-system/federal-greenhouse-gas-offset-system/emission-factors-reference-values.html | W13: Electricity consumption intensity for 2026. Already a combined CO₂e value, so no GWP step is applied. Converted to kg by dividing by 1,000.
B16: How the aggregated factor is built
B17: • Scope 1 rows: Aggregated g CO₂e per activity unit = (CO₂ EF x CO₂ GWP) + (CH₄ EF x CH₄ GWP) + (N₂O EF x N₂O GWP). The result is divided by 1,000 to give kg CO₂e per activity unit.
B18: • Scope 2 rows: ECCC publishes Table 5.3 already in g CO₂e/kWh, so the only step is to divide by 1,000. For example 59 g CO₂e/kWh becomes 0.059 kg CO₂e/kWh. No GWP multiplication is applied, because the gases have already been combined by ECCC.
B19: • The EF Basis column states which of the two routes was used. Where the CO₂e factor was calculated here rather than published by ECCC, the EF Basis column says so.
B20: • GWP values in columns L to N are linked to the GWP Reference sheet. They are shown in green to signal a link to another worksheet.
B21: • Cells marked n/a are not applicable to that row rather than missing. Scope 1 rows have no published CO₂e factor, and Scope 2 rows have no separate gas by gas factors to report.

Sheet GWP Reference
B2: Global Warming Potential Reference
B3: Values used to convert methane and nitrous oxide into carbon dioxide equivalent (CO₂e). These cells feed the aggregated factor formulas on the Emission Factors DB sheet.
B5: Greenhouse Gas | C5: Chemical Formula | D5: GWP | E5: Source | F5: Applicable Year / Version | G5: Source URL
B6: Carbon dioxide | C6: CO₂ | D6: 1 | E6: Greenhouse Gas Pollution Pricing Act, Schedule 3, Column 2 | F6: In force for calendar year 2026 (Act current to 2026) | G6: https://laws-lois.justice.gc.ca/eng/acts/g-11.55/page-28.html
B7: Methane | C7: CH₄ | D7: 28 | E7: Greenhouse Gas Pollution Pricing Act, Schedule 3, Column 2 | F7: In force for calendar year 2026 (Act current to 2026) | G7: https://laws-lois.justice.gc.ca/eng/acts/g-11.55/page-28.html
B8: Nitrous oxide | C8: N₂O | D8: 265 | E8: Greenhouse Gas Pollution Pricing Act, Schedule 3, Column 2 | F8: In force for calendar year 2026 (Act current to 2026) | G8: https://laws-lois.justice.gc.ca/eng/acts/g-11.55/page-28.html
B10: Notes
B11: • These are the 100 year global warming potentials set out in Schedule 3 to the Greenhouse Gas Pollution Pricing Act. They match the IPCC Fifth Assessment Report values.
B12: • GWP is the factor used to express a non CO₂ gas as an equivalent quantity of carbon dioxide. One kilogram of methane counts as 28 kilograms of CO₂e.
B13: • If Schedule 3 is amended, change the values in column D only. Every aggregated factor on the Emission Factors DB sheet updates automatically.
B14: • AR6 (IPCC Sixth Assessment) is not used here even though the GHG Protocol recommends it as the latest science. Canada's Greenhouse Gas Pollution Pricing Act, Schedule 3, which is legally binding for federal carbon pricing / OBPS compliance in 2026 is legislated on AR5 values, and the ECCC emission factors on the Emission Factors DB sheet (Version 3.0, October 2025) are built on that same AR5 basis. Using AR6 (CH₄ non-fossil 27.0, CH₄ fossil 29.8, N₂O 273) would create a mismatch with the statutory factors and misstate compliance totals. Revisit this choice if Schedule 3 is amended, or if this workbook is repurposed for voluntary AR6-aligned disclosure (e.g., CDP, SBTi, ESRS).

Sheet Instructions & Methodology
B2: Instructions and Methodology
B3: Company X by RCC (fictional) | Reporting Calendar Year 2026 | GHG Protocol Corporate Standard
B6: Purpose
B7: This workbook demonstrates Scope 1 and Scope 2 greenhouse gas accounting for Company X by RCC, a fictional Canadian organization with offices in Toronto, Calgary and Vancouver. It was created as a portfolio sample to demonstrate the calculation method, data structure and audit trail behind a corporate GHG inventory.
B8: All company details, facility names and activity quantities are invented. The emission factors are real and come from official Canadian government sources. This sample workbook was created by Reiniel Celgie Chan for demonstration and portfolio purposes. Company X by RCC, its facilities and its activity data are fictional.
B10: Organizational boundary
B11: The inventory uses the operational control approach. The fictional organization is assumed to have operational control over the three offices and over the vehicles in its fleet, so 100 percent of the emissions from those sources are reported.
B12: Reporting period: 1 January 2026 to 31 December 2026. Activity data is recorded quarterly.
B14: Scope 1: direct emissions
B15: Scope 1 covers emissions from sources the organization owns or controls. Two categories are included here.
B16: Stationary combustion: natural gas burned on site for building heating.
B17: Mobile combustion: motor gasoline and diesel burned in company owned vehicles.
... B62: For a tailored version aligned with a company's organizational boundary, operations, emission sources, data availability and reporting requirements, please contact Reiniel Celgie Chan.
B63: =HYPERLINK("mailto:reinielcelgiechan@gmail.com","Email: reinielcelgiechan@gmail.com") -> Email: reinielcelgiechan@gmail.com
B64: =HYPERLINK("https://www.linkedin.com/in/reiniel-celgie-chan-0a122428b/","LinkedIn: Reiniel Celgie Chan") -> LinkedIn: Reiniel Celgie Chan
B65: Limitations
B66: The activity data is fictional and does not represent any real organization.
B67: Fugitive emissions, and any Scope 1 sources beyond the fuels listed, are excluded.
B68: Scope 3 is outside the boundary of this workbook.
B69: Scope 2 is reported on the location based method only.
B70: Emission factors should be rechecked against the ECCC page each reporting year, because ECCC publishes a new set of year specific tables annually.
B72: Reference links
B73: ECCC Emission Factors and Reference Values, Version 3.0 (October 2025) | E73: https://www.canada.ca/en/environment-climate-change/services/climate-change/pricing-pollution-how-it-will-work/output-based-pricing-system/federal-greenhouse-gas-offset-system/emission-factors-reference-values.html
B74: Greenhouse Gas Pollution Pricing Act, Schedule 3 (global warming potentials) | E74: https://laws-lois.justice.gc.ca/eng/acts/g-11.55/page-28.html
